2020-06-27 16:39:44,475 ERROR: Exception on /favicon.ico [GET] [in c:\users\matthew\pycharmprojects\tbh\venv\lib\site-packages\flask\app.py:1892]
Traceback (most recent call last):
  File "c:\users\matthew\pycharmprojects\tbh\venv\lib\site-packages\flask\app.py", line 1950, in full_dispatch_request
    rv = self.dispatch_request()
  File "c:\users\matthew\pycharmprojects\tbh\venv\lib\site-packages\flask\app.py", line 1926, in dispatch_request
    self.raise_routing_exception(req)
  File "c:\users\matthew\pycharmprojects\tbh\venv\lib\site-packages\flask\app.py", line 1908, in raise_routing_exception
    raise request.routing_exception
  File "c:\users\matthew\pycharmprojects\tbh\venv\lib\site-packages\flask\ctx.py", line 350, in match_request
    result = self.url_adapter.match(return_rule=True)
  File "c:\users\matthew\pycharmprojects\tbh\venv\lib\site-packages\werkzeug\routing.py", line 1945, in match
    raise NotFound()
werkzeug.exceptions.NotFound: 404 Not Found: The requested URL was not found on the server. If you entered the URL manually please check your spelling and try again.

During handling of the above exception, another exception occurred:

Traceback (most recent call last):
  File "c:\users\matthew\pycharmprojects\tbh\venv\lib\site-packages\flask\app.py", line 2447, in wsgi_app
    response = self.full_dispatch_request()
  File "c:\users\matthew\pycharmprojects\tbh\venv\lib\site-packages\flask\app.py", line 1952, in full_dispatch_request
    rv = self.handle_user_exception(e)
  File "c:\users\matthew\pycharmprojects\tbh\venv\lib\site-packages\flask\app.py", line 1816, in handle_user_exception
    return self.handle_http_exception(e)
  File "c:\users\matthew\pycharmprojects\tbh\venv\lib\site-packages\flask\app.py", line 1744, in handle_http_exception
    return handler(e)
  File "C:\Users\Matthew\PycharmProjects\tbh\app\errors\handlers.py", line 8, in not_found_error
    return render_template('errors/404.html'), 404
  File "c:\users\matthew\pycharmprojects\tbh\venv\lib\site-packages\flask\templating.py", line 136, in render_template
    ctx.app.update_template_context(context)
  File "c:\users\matthew\pycharmprojects\tbh\venv\lib\site-packages\flask\app.py", line 838, in update_template_context
    context.update(func())
  File "c:\users\matthew\pycharmprojects\tbh\venv\lib\site-packages\flask_login\utils.py", line 379, in _user_context_processor
    return dict(current_user=_get_user())
  File "c:\users\matthew\pycharmprojects\tbh\venv\lib\site-packages\flask_login\utils.py", line 346, in _get_user
    current_app.login_manager._load_user()
  File "c:\users\matthew\pycharmprojects\tbh\venv\lib\site-packages\flask_login\login_manager.py", line 303, in _load_user
    "Missing user_loader or request_loader. Refer to "
Exception: Missing user_loader or request_loader. Refer to http://flask-login.readthedocs.io/#how-it-works for more info.
2020-06-27 16:40:40,081 INFO: TBH App startup [in C:\Users\Matthew\PycharmProjects\tbh\app\__init__.py:65]
2020-06-27 16:40:41,805 ERROR: Exception on / [GET] [in c:\users\matthew\pycharmprojects\tbh\venv\lib\site-packages\flask\app.py:1892]
Traceback (most recent call last):
  File "c:\users\matthew\pycharmprojects\tbh\venv\lib\site-packages\flask\app.py", line 1950, in full_dispatch_request
    rv = self.dispatch_request()
  File "c:\users\matthew\pycharmprojects\tbh\venv\lib\site-packages\flask\app.py", line 1926, in dispatch_request
    self.raise_routing_exception(req)
  File "c:\users\matthew\pycharmprojects\tbh\venv\lib\site-packages\flask\app.py", line 1908, in raise_routing_exception
    raise request.routing_exception
  File "c:\users\matthew\pycharmprojects\tbh\venv\lib\site-packages\flask\ctx.py", line 350, in match_request
    result = self.url_adapter.match(return_rule=True)
  File "c:\users\matthew\pycharmprojects\tbh\venv\lib\site-packages\werkzeug\routing.py", line 1945, in match
    raise NotFound()
werkzeug.exceptions.NotFound: 404 Not Found: The requested URL was not found on the server. If you entered the URL manually please check your spelling and try again.

During handling of the above exception, another exception occurred:

Traceback (most recent call last):
  File "c:\users\matthew\pycharmprojects\tbh\venv\lib\site-packages\flask\app.py", line 2447, in wsgi_app
    response = self.full_dispatch_request()
  File "c:\users\matthew\pycharmprojects\tbh\venv\lib\site-packages\flask\app.py", line 1952, in full_dispatch_request
    rv = self.handle_user_exception(e)
  File "c:\users\matthew\pycharmprojects\tbh\venv\lib\site-packages\flask\app.py", line 1816, in handle_user_exception
    return self.handle_http_exception(e)
  File "c:\users\matthew\pycharmprojects\tbh\venv\lib\site-packages\flask\app.py", line 1744, in handle_http_exception
    return handler(e)
  File "C:\Users\Matthew\PycharmProjects\tbh\app\errors\handlers.py", line 8, in not_found_error
    return render_template('errors/404.html'), 404
  File "c:\users\matthew\pycharmprojects\tbh\venv\lib\site-packages\flask\templating.py", line 136, in render_template
    ctx.app.update_template_context(context)
  File "c:\users\matthew\pycharmprojects\tbh\venv\lib\site-packages\flask\app.py", line 838, in update_template_context
    context.update(func())
  File "c:\users\matthew\pycharmprojects\tbh\venv\lib\site-packages\flask_login\utils.py", line 379, in _user_context_processor
    return dict(current_user=_get_user())
  File "c:\users\matthew\pycharmprojects\tbh\venv\lib\site-packages\flask_login\utils.py", line 346, in _get_user
    current_app.login_manager._load_user()
  File "c:\users\matthew\pycharmprojects\tbh\venv\lib\site-packages\flask_login\login_manager.py", line 303, in _load_user
    "Missing user_loader or request_loader. Refer to "
Exception: Missing user_loader or request_loader. Refer to http://flask-login.readthedocs.io/#how-it-works for more info.
2020-06-27 16:40:41,949 ERROR: Exception on /favicon.ico [GET] [in c:\users\matthew\pycharmprojects\tbh\venv\lib\site-packages\flask\app.py:1892]
Traceback (most recent call last):
  File "c:\users\matthew\pycharmprojects\tbh\venv\lib\site-packages\flask\app.py", line 1950, in full_dispatch_request
    rv = self.dispatch_request()
  File "c:\users\matthew\pycharmprojects\tbh\venv\lib\site-packages\flask\app.py", line 1926, in dispatch_request
    self.raise_routing_exception(req)
  File "c:\users\matthew\pycharmprojects\tbh\venv\lib\site-packages\flask\app.py", line 1908, in raise_routing_exception
    raise request.routing_exception
  File "c:\users\matthew\pycharmprojects\tbh\venv\lib\site-packages\flask\ctx.py", line 350, in match_request
    result = self.url_adapter.match(return_rule=True)
  File "c:\users\matthew\pycharmprojects\tbh\venv\lib\site-packages\werkzeug\routing.py", line 1945, in match
    raise NotFound()
werkzeug.exceptions.NotFound: 404 Not Found: The requested URL was not found on the server. If you entered the URL manually please check your spelling and try again.

During handling of the above exception, another exception occurred:

Traceback (most recent call last):
  File "c:\users\matthew\pycharmprojects\tbh\venv\lib\site-packages\flask\app.py", line 2447, in wsgi_app
    response = self.full_dispatch_request()
  File "c:\users\matthew\pycharmprojects\tbh\venv\lib\site-packages\flask\app.py", line 1952, in full_dispatch_request
    rv = self.handle_user_exception(e)
  File "c:\users\matthew\pycharmprojects\tbh\venv\lib\site-packages\flask\app.py", line 1816, in handle_user_exception
    return self.handle_http_exception(e)
  File "c:\users\matthew\pycharmprojects\tbh\venv\lib\site-packages\flask\app.py", line 1744, in handle_http_exception
    return handler(e)
  File "C:\Users\Matthew\PycharmProjects\tbh\app\errors\handlers.py", line 8, in not_found_error
    return render_template('errors/404.html'), 404
  File "c:\users\matthew\pycharmprojects\tbh\venv\lib\site-packages\flask\templating.py", line 136, in render_template
    ctx.app.update_template_context(context)
  File "c:\users\matthew\pycharmprojects\tbh\venv\lib\site-packages\flask\app.py", line 838, in update_template_context
    context.update(func())
  File "c:\users\matthew\pycharmprojects\tbh\venv\lib\site-packages\flask_login\utils.py", line 379, in _user_context_processor
    return dict(current_user=_get_user())
  File "c:\users\matthew\pycharmprojects\tbh\venv\lib\site-packages\flask_login\utils.py", line 346, in _get_user
    current_app.login_manager._load_user()
  File "c:\users\matthew\pycharmprojects\tbh\venv\lib\site-packages\flask_login\login_manager.py", line 303, in _load_user
    "Missing user_loader or request_loader. Refer to "
Exception: Missing user_loader or request_loader. Refer to http://flask-login.readthedocs.io/#how-it-works for more info.
